<sdf version='1.11'>
  <model name='tortoisebot'>
    <link name='base_footprint'/>
    <link name='base_link'>
      <inertial>
        <pose>0.027272999999999999 0 0.013636000000000001 0 0 0</pose>
        <mass>1.1000000000000001</mass>
        <inertia>
          <ixx>0.017145500000000001</ixx>
          <ixy>0</ixy>
          <ixz>-0.0040909099999999997</ixz>
          <iyy>0.047827300000000003</iyy>
          <iyz>0</iyz>
          <izz>0.045781799999999997</izz>
        </inertia>
      </inertial>
      <collision name='base_link_collision'>
        <pose>0 0 0 0 0 0</pose>
        <geometry>
          <box>
            <size>0.59999999999999998 0.29999999999999999 0.29999999999999999</size>
          </box>
        </geometry>
      </collision>
      <visual name='base_link_visual'>
        <pose>0 0 0 0 0 0</pose>
        <geometry>
          <box>
            <size>0.59999999999999998 0.29999999999999999 0.29999999999999999</size>
          </box>
        </geometry>
        <material>
          <ambient>0.5 0.5 0.5 1</ambient>
          <diffuse>0.5 0.5 0.5 1</diffuse>
        </material>
      </visual>
    </link>
    <joint name='base_footprint_joint' type='fixed'>
      <parent>base_footprint</parent>
      <child>base_link</child>
      <pose>0 0 0.14999999999999999 0 0 0</pose>
    </joint>
    <link name='lidar_link'>
      <inertial>
        <pose>0.29999999999999999 0 0.14999999999999999 0 0 0</pose>
        <mass>0.050000000000000003</mass>
        <inertia>
          <ixx>6.2500000000000003e-06</ixx>
          <ixy>0</ixy>
          <ixz>0</ixz>
          <iyy>6.2500000000000003e-06</iyy>
          <iyz>0</iyz>
          <izz>6.2500000000000003e-06</izz>
        </inertia>
      </inertial>
      <collision name='lidar_link_collision'>
        <pose>0.29999999999999999 0 0.14999999999999999 0 0 0</pose>
        <geometry>
          <cylinder>
            <length>0.050000000000000003</length>
            <radius>0.050000000000000003</radius>
          </cylinder>
        </geometry>
        <surface>
          <contact>
            <ode/>
          </contact>
          <friction>
            <ode/>
          </friction>
        </surface>
      </collision>
      <visual name='lidar_link_visual'>
        <pose>0.29999999999999999 0 0.14999999999999999 0 0 0</pose>
        <geometry>
          <cylinder>
            <length>0.01</length>
            <radius>0.02</radius>
          </cylinder>
        </geometry>
        <material>
          <ambient>0 1 0 1</ambient>
          <diffuse>0 1 0 1</diffuse>
        </material>
      </visual>
      <sensor name='lidar_sensor' type='gpu_lidar'>
        <pose>0.29999999999999999 0 0.14999999999999999 0 0 0</pose>
        <topic>scan</topic>
        <update_rate>30</update_rate>
        <lidar>
          <scan>
            <horizontal>
              <samples>360</samples>
              <resolution>1</resolution>
              <min_angle>-3.1400000000000001</min_angle>
              <max_angle>3.1400000000000001</max_angle>
            </horizontal>
            <vertical>
              <samples>1</samples>
              <resolution>1</resolution>
              <min_angle>0</min_angle>
              <max_angle>0</max_angle>
            </vertical>
          </scan>
          <range>
            <min>0.12</min>
            <max>3.5</max>
            <resolution>0.01</resolution>
          </range>
          <noise>
            <type>gaussian</type>
            <mean>0</mean>
            <stddev>0.01</stddev>
          </noise>
        </lidar>
        <always_on>true</always_on>
        <visualize>true</visualize>
      </sensor>
    </link>
    <joint name='lidar_joint' type='fixed'>
      <pose relative_to='base_link'>0.29999999999999999 0 0.20000000000000001 0 0 0</pose>
      <parent>base_link</parent>
      <child>lidar_link</child>
    </joint>
    <joint name='front_caster_joint' type='revolute'>
      <pose relative_to='base_link'>0.29999999999999999 0 0 0 0 0</pose>
      <parent>base_link</parent>
      <child>front_caster</child>
      <axis>
        <xyz>0 0 1</xyz>
        <limit>
          <lower>-10000000000000000</lower>
          <upper>10000000000000000</upper>
        </limit>
        <dynamics>
          <spring_reference>0</spring_reference>
          <spring_stiffness>0</spring_stiffness>
        </dynamics>
      </axis>
    </joint>
    <link name='front_caster'>
      <pose relative_to='front_caster_joint'>0 0 0 0 0 0</pose>
      <inertial>
        <pose>0 0 0 0 0 0</pose>
        <mass>0.10000000000000001</mass>
        <inertia>
          <ixx>0.00083000000000000001</ixx>
          <ixy>0</ixy>
          <ixz>0</ixz>
          <iyy>0.00083000000000000001</iyy>
          <iyz>0</iyz>
          <izz>0.00016699999999999999</izz>
        </inertia>
      </inertial>
      <collision name='front_caster_collision'>
        <pose>0 0 0 0 0 0</pose>
        <geometry>
          <box>
            <size>0.10000000000000001 0.10000000000000001 0.29999999999999999</size>
          </box>
        </geometry>
      </collision>
      <visual name='front_caster_visual'>
        <pose>0 0 0 0 0 0</pose>
        <geometry>
          <box>
            <size>0.10000000000000001 0.10000000000000001 0.29999999999999999</size>
          </box>
        </geometry>
        <material>
          <ambient>0.200000003 0.200000003 0.800000012 1</ambient>
          <diffuse>0.200000003 0.200000003 0.800000012 1</diffuse>
        </material>
      </visual>
    </link>
    <joint name='front_wheel_joint' type='revolute'>
      <pose relative_to='front_caster'>0.050000000000000003 0 -0.14999999999999999 -1.5708 0 0</pose>
      <parent>front_caster</parent>
      <child>front_wheel</child>
      <axis>
        <xyz>0 0 1</xyz>
        <limit>
          <lower>-10000000000000000</lower>
          <upper>10000000000000000</upper>
        </limit>
        <dynamics>
          <spring_reference>0</spring_reference>
          <spring_stiffness>0</spring_stiffness>
        </dynamics>
      </axis>
    </joint>
    <link name='front_wheel'>
      <pose relative_to='front_wheel_joint'>0 0 0 0 0 0</pose>
      <inertial>
        <pose>0 0 0 0 0 0</pose>
        <mass>0.10000000000000001</mass>
        <inertia>
          <ixx>5.1458000000000001e-05</ixx>
          <ixy>0</ixy>
          <ixz>0</ixz>
          <iyy>5.1458000000000001e-05</iyy>
          <iyz>0</iyz>
          <izz>6.1249999999999998e-05</izz>
        </inertia>
      </inertial>
      <collision name='front_wheel_collision'>
        <pose>0 0 0 0 0 0</pose>
        <geometry>
          <cylinder>
            <length>0.050000000000000003</length>
            <radius>0.035000000000000003</radius>
          </cylinder>
        </geometry>
      </collision>
      <visual name='front_wheel_visual'>
        <pose>0 0 0 0 0 0</pose>
        <geometry>
          <cylinder>
            <length>0.050000000000000003</length>
            <radius>0.035000000000000003</radius>
          </cylinder>
        </geometry>
        <material>
          <ambient>0.100000001 0.100000001 0.100000001 1</ambient>
          <diffuse>0.100000001 0.100000001 0.100000001 1</diffuse>
        </material>
      </visual>
    </link>
    <joint name='left_wheel_joint' type='revolute'>
      <pose relative_to='base_link'>-0.28249999999999997 0.125 -0.14999999999999999 -1.5708 0 0</pose>
      <parent>base_link</parent>
      <child>left_wheel</child>
      <axis>
        <xyz>0 0 1</xyz>
        <limit>
          <lower>-10000000000000000</lower>
          <upper>10000000000000000</upper>
        </limit>
        <dynamics>
          <spring_reference>0</spring_reference>
          <spring_stiffness>0</spring_stiffness>
        </dynamics>
      </axis>
    </joint>
    <link name='left_wheel'>
      <pose relative_to='left_wheel_joint'>0 0 0 0 0 0</pose>
      <inertial>
        <pose>0 0 0 0 0 0</pose>
        <mass>0.10000000000000001</mass>
        <inertia>
          <ixx>5.1458000000000001e-05</ixx>
          <ixy>0</ixy>
          <ixz>0</ixz>
          <iyy>5.1458000000000001e-05</iyy>
          <iyz>0</iyz>
          <izz>6.1249999999999998e-05</izz>
        </inertia>
      </inertial>
      <collision name='left_wheel_collision'>
        <pose>0 0 0 0 0 0</pose>
        <geometry>
          <cylinder>
            <length>0.050000000000000003</length>
            <radius>0.035000000000000003</radius>
          </cylinder>
        </geometry>
      </collision>
      <visual name='left_wheel_visual'>
        <pose>0 0 0 0 0 0</pose>
        <geometry>
          <cylinder>
            <length>0.050000000000000003</length>
            <radius>0.035000000000000003</radius>
          </cylinder>
        </geometry>
        <material>
          <ambient>0.100000001 0.100000001 0.100000001 1</ambient>
          <diffuse>0.100000001 0.100000001 0.100000001 1</diffuse>
        </material>
      </visual>
    </link>
    <joint name='right_wheel_joint' type='revolute'>
      <pose relative_to='base_link'>-0.28249999999999997 -0.125 -0.14999999999999999 -1.5708 0 0</pose>
      <parent>base_link</parent>
      <child>right_wheel</child>
      <axis>
        <xyz>0 0 1</xyz>
        <limit>
          <lower>-10000000000000000</lower>
          <upper>10000000000000000</upper>
        </limit>
        <dynamics>
          <spring_reference>0</spring_reference>
          <spring_stiffness>0</spring_stiffness>
        </dynamics>
      </axis>
    </joint>
    <link name='right_wheel'>
      <pose relative_to='right_wheel_joint'>0 0 0 0 0 0</pose>
      <inertial>
        <pose>0 0 0 0 0 0</pose>
        <mass>0.10000000000000001</mass>
        <inertia>
          <ixx>5.1458000000000001e-05</ixx>
          <ixy>0</ixy>
          <ixz>0</ixz>
          <iyy>5.1458000000000001e-05</iyy>
          <iyz>0</iyz>
          <izz>6.1249999999999998e-05</izz>
        </inertia>
      </inertial>
      <collision name='right_wheel_collision'>
        <pose>0 0 0 0 0 0</pose>
        <geometry>
          <cylinder>
            <length>0.050000000000000003</length>
            <radius>0.035000000000000003</radius>
          </cylinder>
        </geometry>
      </collision>
      <visual name='right_wheel_visual'>
        <pose>0 0 0 0 0 0</pose>
        <geometry>
          <cylinder>
            <length>0.050000000000000003</length>
            <radius>0.035000000000000003</radius>
          </cylinder>
        </geometry>
        <material>
          <ambient>0.100000001 0.100000001 0.100000001 1</ambient>
          <diffuse>0.100000001 0.100000001 0.100000001 1</diffuse>
        </material>
      </visual>
    </link>
    <static>false</static>
    <plugin name='gz::sim::systems::DiffDrive' filename='gz-sim-diff-drive-system'>
      <left_joint>left_wheel_joint</left_joint>
      <right_joint>right_wheel_joint</right_joint>
      <wheel_separation>0.25</wheel_separation>
      <wheel_radius>0.035</wheel_radius>
      <odom_publish_frequency>50</odom_publish_frequency>
      <topic>cmd_vel</topic>
      <odom_topic>odom</odom_topic>
      <frame_id>odom</frame_id>
      <child_frame_id>base_footprint</child_frame_id>
    </plugin>
    <plugin name='ros_gz_sim::systems::Ros2Bridge' filename='gz-sim-ros2-system'>
      <ros>
        <namespace>/</namespace>
        <remapping>odom:=odom</remapping>
        <remapping>cmd_vel:=cmd_vel</remapping>
        <remapping>joint_states:=joint_states</remapping>
      </ros>
    </plugin>
    <plugin name='gz::sim::systems::JointStatePublisher' filename='gz-sim-joint-state-publisher-system'>
      <topic>joint_states</topic>
      <joint_name>left_wheel_joint</joint_name>
      <joint_name>right_wheel_joint</joint_name>
      <joint_name>front_caster_joint</joint_name>
      <joint_name>front_wheel_joint</joint_name>
    </plugin>
    <plugin name='gz::sim::systems::OdometryPublisher' filename='gz-sim-odometry-publisher-system'>
      <odom_frame>odom</odom_frame>
      <robot_base_frame>base_footprint</robot_base_frame>
      <odom_publish_frequency>50</odom_publish_frequency>
      <odom_topic>/odom</odom_topic>
      <tf_topic>/tf</tf_topic>
    </plugin>
    <plugin name='gz::sim::systems::Sensors' filename='gz-sim-sensors-system'>
      <render_engine>ogre2</render_engine>
    </plugin>
    <plugin name='gz::sim::systems::Tf' filename='gz-sim-tf-system'>
      <publish_tf>true</publish_tf>
      <publish_static_tf>true</publish_static_tf>
      <tf_topic>/tf</tf_topic>
      <static_tf_topic>/tf_static</static_tf_topic>
    </plugin>
  </model>
</sdf>
